<mujoco model="UR3">
    <compiler angle="radian" />
    <asset>
        <mesh name="link1-v4" file="meshes/link1-v4.stl" scale="0.001 0.001 0.001" />
        <mesh name="base_link-v3" file="meshes/base_link-v3.stl" scale="0.001 0.001 0.001" />
        <mesh name="link2-v3" file="meshes/link2-v3.stl" scale="0.001 0.001 0.001" />
        <mesh name="link3-v3" file="meshes/link3-v3.stl" scale="0.001 0.001 0.001" />
        <mesh name="link4-v3" file="meshes/link4-v3.stl" scale="0.001 0.001 0.001" />
        <mesh name="link5-v3" file="meshes/link5-v3.stl" scale="0.001 0.001 0.001" />
        <mesh name="link6-v3" file="meshes/link6-v3.stl" scale="0.001 0.001 0.001" />
        <mesh name="Left_Grip" file="meshes/Left_Grip.stl" scale="0.001 0.001 0.001" />
        <mesh name="Right_Grip" file="meshes/Right_Grip.stl" scale="0.001 0.001 0.001" />
        <mesh name="Door" file="meshes/Door.stl" scale="0.001 0.001 0.001" />
    </asset>
    <worldbody>
        <light directional="true" pos="-0.5 0.5 3" dir="0 0 -1" />
        <geom pos="0 0 0" size="1 1 1" type="plane" rgba="1 0.83 0.61 0.5" />
        <body name="base_link-v3" pos="-7.815158320407879e-16 0.01722310771811039 0.06789999641118911" euler="1.5200514458246762e-16 7.028391405114113e-16 -7.014997688363869e-16">
            <geom name="base_link-v3_geom" type="mesh" mesh="base_link-v3" pos="0 0 0" euler="0 0 0" />
            <inertial mass="1262.2618288508525" pos="-0.5402398621610146 -0.8895005162969064 0.06846508640851184" fullinertia="319.47349657560926 151.81704540196995 410.2684067124868 -51.92911277900437 -1.8267157142938322 -20.66460241756543" />
            <body name="link1-v4" pos="0.00017721710714233585 -0.02119581809949581 0.10461075851854176" euler="1.5713279126393407 1.001341137378472e-15 -5.864639019602619e-16">
                <joint name="shoulder_pan" type="hinge" axis="-1.2889400978189644e-15 1.0000001415119044 4.1410542506203126e-07" pos="-0.000136217107141533 -0.060837895381651304 -0.004010370385550103" />
                <geom name="link1-v4_geom" type="mesh" mesh="link1-v4" pos="0 0 0" euler="0 0 0" />
                <inertial mass="0.3149483948341394" pos="-0.0002652338271638842 0.049132603623666324 -0.00923732563322702" fullinertia="0.00023120994782054732 0.00040742337943199957 0.00024406222096013156 -6.830148326541122e-07 9.204290047829193e-07 -5.209320715751602e-05" />
                <body name="link2-v3" pos="0.006294247901650221 0.1220597401976195 0.110930373764038" euler="-1.5707963267948966 -6.768470874919664e-17 -3.141592653589793">
                    <joint name="shoulder_lift" type="hinge" axis="3.4187444195032947e-16 1.0000001415119044 -4.141054250247347e-07" pos="0.0060874650087918555 -0.060940742889264675 -0.11704492063990748" />
                    <geom name="link2-v3_geom" type="mesh" mesh="link2-v3" pos="0 0 0" euler="0 0 0" />
                    <inertial mass="8.393606609808884" pos="0.0035734055358095976 0.006609948834613911 0.052247493219949634" fullinertia="0.05159083523063959 0.05262580208406281 0.0077648716948884415 -5.210447077515836e-05 0.0016092328510568 0.0024027602235542657" />
                    <body name="link3-v3" pos="0.1005558571423142 0.0029199794744266504 0.2402547302285521" euler="-1.537430973977361 0.04238013883889145 1.6028239938980364">
                        <joint name="elbow" type="hinge" axis="-0.03179292567459977 -0.998334907825896 0.04812335416728601" pos="0.11526944514168323 0.04828746610328463 -0.0036622252497880516" />
                        <geom name="link3-v3_geom" type="mesh" mesh="link3-v3" pos="0 0 0" euler="0 0 0" />
                        <inertial mass="7.526132329492665" pos="0.002697801977457159 0.00600645740159372 0.001739382994739837" fullinertia="0.005103753670418879 0.05584573389089698 0.057052325569695375 -0.0029985968034238046 0.001714037463513435 0.0001480332172012595" />
                        <body name="link4-v3" pos="-0.09394264528548839 0.08517827079539464 0.003104782137911446" euler="-0.044918708823939495 0.017473795330266727 -0.07858593549021095">
                            <joint name="wrist_1" type="hinge" axis="-0.0466801496070125 0.9989094651397883 0.00037384463154951003" pos="-0.0008000942484049022 -0.038453066782212435 -0.0019143563709908334" />
                            <geom name="link4-v3_geom" type="mesh" mesh="link4-v3" pos="0 0 0" euler="0 0 0" />
                            <inertial mass="2.545842238140852" pos="-0.0017869411138814418 0.00021015812296798112 -0.0019185778391200628" fullinertia="0.001605181557207053 0.002093426217229627 0.002391020327025471 -1.5967007851733523e-05 1.7044927996070516e-05 5.064283854269504e-07" />
                            <body name="link5-v3" pos="-0.08227103879236118 4.7038623188369045e-05 -0.0009760318154197556" euler="-2.622197027745017 1.490207513311002 2.6303272677564338">
                                <joint name="wrist_2" type="hinge" axis="0.04813268153388546 -0.007095977382246862 -0.998815833429942" pos="-0.002837110941871986 0.002720336118535904 0.036873853408285806" />
                                <geom name="link5-v3_geom" type="mesh" mesh="link5-v3" pos="0 0 0" euler="0 0 0" />
                                <inertial mass="2.545842534539693" pos="-0.0009810150077491488 0.001907092188005187 -0.0017442445659119404" fullinertia="0.0023410122037799313 0.0016046358626508879 0.00204471909767193 -6.292065784448897e-06 1.4479325932616191e-05 1.58767883765228e-05" />
                                <body name="link6-v3" pos="0.0003712756726844724 0.062732144495235 -0.008819264338478518" euler="1.6206642382715735 0.12856522039449575 2.6677995944018904">
                                    <joint name="wrist_3" type="hinge" axis="-0.14666389306905664 -0.011638930895147632 -0.989118372880861" pos="0.0034512935236635854 -0.00018795006317411502 0.017426662117023865" />
                                    <geom name="link6-v3_geom" type="mesh" mesh="link6-v3" pos="0 0 0" euler="0 0 0" />
                                    <inertial mass="2.514608875710969" pos="-0.0034173450650849964 -0.0028923602265742998 -0.04713742240637238" fullinertia="0.004689205158946851 0.004793282848165315 0.0013500750637262234 -0.00011499222724200165 -0.00024679280563782774 -0.00018903876337133136" />
                                    <body name="Left_Grip" pos="-0.0028920768200609358 -0.0005494197618841668 -0.02730684271749295" euler="-1.4980880985706329 -0.517366751832628 -2.9670597283903613">
                                        <joint name="link6-v3_Grip-Driver" type="hinge" axis="-7.901738295515263e-08 -1.1821091312600555e-07 1.0000002520679705" pos="0.01619987163589032 -0.06649982799046604 0.022500022719879307" />
                                        <geom name="Left_Grip_geom" type="mesh" mesh="Left_Grip" pos="0 0 0" euler="0 0 0" />
                                        <inertial mass="0.217026367003884" pos="0.029455054908694586 -0.12865041530667387 0.023692316225595512" fullinertia="0.0004421610099300489 4.940210539014101e-05 0.0004879125423265275 3.5286502567110514e-05 4.6462981783112754e-07 -2.1041578673544226e-06" />
                                    </body>
                                    <body name="Right_Grip" pos="-0.0028681011958032344 -0.0005473446227640011 -0.027147515905335946" euler="-1.4980880985706326 -0.5173667518326286 -2.9670597283903617">
                                        <joint name="link6-v3_Grip-Link" type="hinge" axis="-7.901738471513802e-08 -1.182109113764302e-07 1.0000002520679723" pos="-0.016199700673337706 -0.06649977596346682 0.017500022413175942" />
                                        <geom name="Right_Grip_geom" type="mesh" mesh="Right_Grip" pos="0 0 0" euler="0 0 0" />
                                        <inertial mass="0.23937395946991255" pos="-0.028331985000097062 -0.1239345457011289 0.02347646263565032" fullinertia="0.0004962113899350675 5.2784553711957736e-05 0.000545007379174274 -4.829421538153547e-05 6.374934035707559e-08 3.6397886365416255e-07" />
                                    </body>
                                </body>
                            </body>
                        </body>
                    </body>
                </body>
            </body>
            <body name="Door" pos="-0.3746089691512519 -0.783676222780528 -0.03338749641118897" euler="5.625060218749189e-16 -1.2796422673385683e-16 1.5707963267948972">
                <joint name="base_link-v3_jM" type="hinge" axis="7.115838226387957e-16 8.66307515512804e-16 1.0" pos="-0.3778248849375845 3.084874780443701e-08 0.16522550000000014" />
                <geom name="Door_geom" type="mesh" mesh="Door" pos="0 0 0" euler="0 0 0" />
                <inertial mass="113.97162766322674" pos="-0.06341457521098175 -0.035604245822519996 0.16531556735525063" fullinertia="1.0823810161326683 4.772928355180978 3.791718009580052 0.021868860400764027 -0.0029158881559128926 0.000607468344471756" />
            </body>
        </body>
    </worldbody>
</mujoco>