<mujoco model="UR3">
    <compiler angle="radian" />
    <asset>
        <mesh name="link1-v4" file="meshes/link1-v4.stl" scale="0.001 0.001 0.001" />
        <mesh name="base_link-v3" file="meshes/base_link-v3.stl" scale="0.001 0.001 0.001" />
        <mesh name="link2-v3" file="meshes/link2-v3.stl" scale="0.001 0.001 0.001" />
        <mesh name="link3-v3" file="meshes/link3-v3.stl" scale="0.001 0.001 0.001" />
        <mesh name="link4-v3" file="meshes/link4-v3.stl" scale="0.001 0.001 0.001" />
        <mesh name="link5-v3" file="meshes/link5-v3.stl" scale="0.001 0.001 0.001" />
        <mesh name="link6-v3" file="meshes/link6-v3.stl" scale="0.001 0.001 0.001" />
    </asset>
    <worldbody>
        <light directional="true" pos="-0.5 0.5 3" dir="0 0 -1" />
        <geom pos="0 0 0" size="1 1 1" type="plane" rgba="1 0.83 0.61 0.5" />
        <body name="base_link-v3" pos="0.0 0.0 0.0425" euler="-0.0 0.0 -6.5052130349130235e-18">
            <geom name="base_link-v3_geom" type="mesh" mesh="base_link-v3" pos="0 0 0" euler="0 0 0" />
            <inertial mass="4.819767656359503" pos="-5.106034955521863e-05 -0.016332230855220346 0.003953847461743631" fullinertia="0.006237181628739425 0.006116331922340007 0.008054234532667305 1.938536735441771e-05 -1.7470323254963813e-05 0.00014640204534811205" />
            <body name="link1-v4" pos="0.00017721710714229611 -0.02119581809949577 0.10461075851854185" euler="1.5713279126393402 -8.474091755303828e-33 2.256949153578789e-36">
                <joint name="base_link-v3_j1" type="hinge" axis="3.460773334570648e-21 1.000000141511904 4.141054253019652e-07" pos="-0.00013621710714229563 -0.06083789902772309 -0.004010478101737522" />
                <geom name="link1-v4_geom" type="mesh" mesh="link1-v4" pos="0 0 0" euler="0 0 0" />
                <inertial mass="0.3149483948341394" pos="-0.00026523382716388396 0.04913260362366625 -0.009237325633227001" fullinertia="0.00023120994782054543 0.0004074233794319988 0.00024406222096013278 -6.830148326541089e-07 9.204290047829156e-07 -5.209320715751612e-05" />
                <body name="link2-v3" pos="0.006294247901650241 0.12205974019761957 0.11083037376403816" euler="-1.5707963267948966 1.224646799159157e-16 -3.141592653589793">
                    <joint name="link1-v4_j2" type="hinge" axis="-6.505263748201317e-18 1.0000001415119049 -4.1410542530174836e-07" pos="0.006087465008792522 -0.06084085060545213 -0.11704492428597922" />
                    <geom name="link2-v3_geom" type="mesh" mesh="link2-v3" pos="0 0 0" euler="0 0 0" />
                    <inertial mass="8.39414664490839" pos="0.003572993655582223 0.006656270016497994 0.05224937869459404" fullinertia="0.051590069759379256 0.052626722074487764 0.007764098511621637 -2.6787056217300834e-05 0.0016094650478816275 0.0023744386233859687" />
                    <body name="link3-v3" pos="0.10045134298988855 0.005243067501151337 0.24027738640715915" euler="-1.5723298162395414 0.05983020746937668 1.6026494098747472">
                        <joint name="link2-v3_j3" type="hinge" axis="-0.03179268051239002 -0.9983356048569957 0.04812337835869409" pos="0.11526664065715334 0.04818741981713634 -0.0036570430137521765" />
                        <geom name="link3-v3_geom" type="mesh" mesh="link3-v3" pos="0 0 0" euler="0 0 0" />
                        <inertial mass="7.526132329492658" pos="0.0026983442315625865 0.006042976365779464 0.0017157725936832726" fullinertia="0.0051007503145706215 0.05584323138798228 0.057051631681898585 -0.0029863817545793645 0.0017003536610661679 0.00011273379986958943" />
                        <body name="link4-v3" pos="-0.093887928397642 0.08512929771671882 0.006740809178398965" euler="-0.0018355888931882909 2.9854826446472786e-05 -0.0798670520737383">
                            <joint name="link3-v3_j4" type="hinge" axis="-0.046679492549142075 0.9989096451765861 0.00037340667036001805" pos="-0.0008053049444286388 -0.03835331465967131 -0.001914233658937797" />
                            <geom name="link4-v3_geom" type="mesh" mesh="link4-v3" pos="0 0 0" euler="0 0 0" />
                            <inertial mass="2.545842238140852" pos="-0.0017869411138815119 0.0002101581229679827 -0.0019185778391200498" fullinertia="0.0016051815572070368 0.00209342621722923 0.0023910203270252795 -1.5967007851728075e-05 1.7044927995913852e-05 5.064283854278321e-07" />
                            <body name="link5-v3" pos="-0.082170270217758 4.238125448672303e-05 -0.0009568090354241932" euler="-2.6263705768793137 1.4904678006051626 2.625771003607149">
                                <joint name="link4-v3_j5" type="hinge" axis="0.04813300752205177 -0.007095577175389419 -0.9988159220644361" pos="-0.0028326447193942213 0.002719985772956658 0.03677382563334695" />
                                <geom name="link5-v3_geom" type="mesh" mesh="link5-v3" pos="0 0 0" euler="0 0 0" />
                                <inertial mass="2.545842534539693" pos="-0.0009810150077491399 0.0019070921880051748 -0.001744244565911893" fullinertia="0.0023410122037799365 0.001604635862650408 0.002044719097671915 -6.292065784463836e-06 1.4479325932626776e-05 1.5876788376516656e-05" />
                                <body name="link6-v3" pos="0.0003959637341796629 0.06263208973460367 -0.008797675417842755" euler="1.6158492493061463 0.1304558458923421 2.702948253139903">
                                    <joint name="link5-v3_j6" type="hinge" axis="-0.1466631170670577 -0.01163870529046814 -0.9891177324769465" pos="0.0034366391161721093 -0.00018947354926481246 0.01732744420292544" />
                                    <geom name="link6-v3_geom" type="mesh" mesh="link6-v3" pos="0 0 0" euler="0 0 0" />
                                    <inertial mass="0.9016744779321996" pos="0.0006390914896667076 -0.0004967267632319083 -0.0018474851847991292" fullinertia="0.00033984520440414706 0.00033787128837576907 0.00045673272192914256 -5.001825509181874e-07 1.8126184747990864e-05 8.087316870065864e-07" />
                                </body>
                            </body>
                        </body>
                    </body>
                </body>
            </body>
        </body>
    </worldbody>
</mujoco>